Workbook

Sheet Implants
A1: Name | B1: Object ID | C1: Install location | D1: Grade | E1: Cost (¥) | F1: Underground cost (¥) | G1: Armor | H1: Armor applies to | I1: Durability | J1: Power draw (kJ/h) | K1: Quality fee (¥/visit) | L1: Skills / stats modified | M1: Nanohacks permitted | N1: Install requirements | O1: Other benefits / maluses
A2: Neural Link | B2: trl_imp_cortex | C2: Head / cortex | D2: 3 | E2: 4200 | F2: =ROUND(E2*0.8,0) -> 3360 | G2: 1 | H2: head | I2: 30 | J2: =2*2^(MAX(D2-2,0)) -> 4 | K2: =MIN(MAX(D2-1,1),3)*100 -> 200 | L2: +4% to hit; aim speed +0.25 | N2: None (buy, empty slot) | O2: Wireless interface and skull lattice. Live.
A3: Optic Suite | B3: trl_imp_optics | C3: Eyes | D3: 2 | E3: 1800 | F3: =ROUND(E3*0.8,0) -> 1440 | G3: 0 | I3: 20 | J3: =2*2^(MAX(D3-2,0)) -> 2 | K3: =MIN(MAX(D3-1,1),3)*100 -> 100 | L3: +2% to hit; +5% more at 5+ tiles | N3: None (buy, empty slot) | O3: Ranging overlay. Live.
A4: Thermal Vision | B4: trl_imp_thermal | C4: Eyes | D4: 2 | E4: 2600 | F4: =ROUND(E4*0.8,0) -> 2080 | G4: 0 | I4: 20 | J4: =2*2^(MAX(D4-2,0)) -> 2 | K4: =MIN(MAX(D4-1,1),3)*100 -> 100 | L4: +3% to hit | N4: None (buy, empty slot) | O4: Warm bodies show through cover and smoke. Live.
A5: Dorsal Jump Jets | B5: trl_imp_jets | C5: Spine | D5: 2 | E5: 3000 | F5: =ROUND(E5*0.8,0) -> 2400 | G5: 0 | I5: 20 | J5: =2*2^(MAX(D5-2,0)) -> 2 | K5: =MIN(MAX(D5-1,1),3)*100 -> 100 | N5: None (buy, empty slot) | O5: Short flight; no falling damage while fuel lasts. Live.
A6: Reflex Wires | B6: trl_imp_reflex | C6: Spine | D6: 3 | E6: 6200 | F6: =ROUND(E6*0.8,0) -> 4960 | G6: 0 | I6: 20 | J6: =2*2^(MAX(D6-2,0)) -> 4 | K6: =MIN(MAX(D6-1,1),3)*100 -> 200 | L6: Aim +0.5; dodge blades +10%; dodge bullets +14%; attack speed +10 | N6: None (buy, empty slot) | O6: Grade 3+ can dodge bullets. Live.
A7: Synapse Accelerator | B7: trl_imp_synapse | C7: Spine | D7: 4 | E7: 11000 | F7: =ROUND(E7*0.8,0) -> 8800 | G7: 0 | I7: 20 | J7: =2*2^(MAX(D7-2,0)) -> 8 | K7: =MIN(MAX(D7-1,1),3)*100 -> 300 | L7: Aim +0.5; dodge blades +18%; dodge bullets +26%; attack speed +20 | N7: None (buy, empty slot) | O7: Military grade. Live.
A8: Dermal Plating | B8: trl_imp_dermal | C8: Dermal | D8: 2 | E8: 2200 | F8: =ROUND(E8*0.8,0) -> 1760 | G8: 2 | H8: all limbs | I8: 80 | J8: =2*2^(MAX(D8-2,0)) -> 2 | K8: =MIN(MAX(D8-1,1),3)*100 -> 100 | N8: None (buy, empty slot) | O8: Stops working when plating wears through. Live.
A9: Mantis Blades | B9: trl_imp_mantis | C9: Arms | D9: 3 | E9: 3400 | F9: =ROUND(E9*0.8,0) -> 2720 | G9: 1 | H9: arms | I9: 30 | J9: =2*2^(MAX(D9-2,0)) -> 4 | K9: =MIN(MAX(D9-1,1),3)*100 -> 200 | L9: Attack speed +15 | N9: None (buy, empty slot) | O9: Unfold when hands are empty; cannot be knocked away. Live.
A10: Smartlink Palm | B10: trl_imp_smartlink | C10: Hands | D10: 2 | E10: 1500 | F10: =ROUND(E10*0.8,0) -> 1200 | G10: 0 | I10: 20 | J10: =2*2^(MAX(D10-2,0)) -> 2 | K10: =MIN(MAX(D10-1,1),3)*100 -> 100 | L10: +8% to hit with any firearm; aim +0.1 | N10: None (buy, empty slot) | O10: Gun-to-hand link. Live.
A11: Leg Actuators | B11: trl_imp_legs | C11: Legs | D11: 2 | E11: 1600 | F11: =ROUND(E11*0.8,0) -> 1280 | G11: 1 | H11: legs | I11: 40 | J11: =2*2^(MAX(D11-2,0)) -> 2 | K11: =MIN(MAX(D11-1,1),3)*100 -> 100 | N11: None (buy, empty slot) | O11: Long jumps; softer landings. Live.
A12: Cardiac Booster | B12: trl_imp_heart | C12: Chest / organs | D12: 2 | E12: 2800 | F12: =ROUND(E12*0.8,0) -> 2240 | G12: 1 | H12: chest | I12: 30 | J12: =2*2^(MAX(D12-2,0)) -> 2 | K12: =MIN(MAX(D12-1,1),3)*100 -> 100 | N12: None (buy, empty slot) | O12: Planned: bigger stamina reserve. NOT LIVE.
A13: Gecko Grip | B13: trl_imp_grip | C13: Hands | D13: 2 | E13: 1700 | F13: =ROUND(E13*0.8,0) -> 1360 | G13: 0 | I13: 20 | J13: =2*2^(MAX(D13-2,0)) -> 2 | K13: =MIN(MAX(D13-1,1),3)*100 -> 100 | N13: None (buy, empty slot) | O13: Planned: climb sheer walls. NOT LIVE.

Sheet Example Implants
A1: Name | B1: Object ID | C1: Install location | D1: Grade | E1: Cost (¥) | F1: Underground cost (¥) | G1: Armor | H1: Armor applies to | I1: Durability (also health) | J1: Latent draw (kJ/h) | K1: Battery (kJ) | L1: Quality fee / repair at 100% damage (¥) | M1: Recharge cost, one week of this implant (¥) | N1: Full battery recharge cost (¥) | O1: Skills modified | P1: Nanohacks permitted | Q1: Install requirements | R1: Other benefits / maluses
A2: Gutterline Trilobit | B2: trl_imp_x101 | C2: Head / cortex | D2: 1 | E2: 10000 | F2: =ROUND(E2*0.8,0) -> 8000 | G2: 1 | H2: head | I2: 16 | J2: ='Power Model'!$B$3*2^(D2-2) -> 0.5 | L2: =ROUND(E2*'Power Model'!$B$11,0) -> 2500 | M2: =ROUND(J2*'Power Model'!$B$4*('Power Model'!$B$7*'Power Model'!$B$8+'Power Model'!$B$9)+E2*'Power Model'!$B$10/100,0) -> 592 | O2: Networking +1 | P2: 2 | Q2: Networking 2 | R2: Brain implant: holds 2 nanohack slots. Durability gain is minimal. Cheap clinic parts: wear out faster, rattle under load.
A3: Kowloon Surplus Trilobit | B3: trl_imp_x102 | C3: Head / cortex | D3: 1 | E3: 10400 | F3: =ROUND(E3*0.8,0) -> 8320 | G3: 1 | H3: head | I3: 18 | J3: ='Power Model'!$B$3*2^(D3-2) -> 0.5 | L3: =ROUND(E3*'Power Model'!$B$11,0) -> 2600 | M3: =ROUND(J3*'Power Model'!$B$4*('Power Model'!$B$7*'Power Model'!$B$8+'Power Model'!$B$9)+E3*'Power Model'!$B$10/100,0) -> 612 | O3: Analysis +1 | P3: 2 | Q3: Analysis 2 | R3: Brain implant: holds 2 nanohack slots. Durability gain is minimal. Cheap clinic parts: wear out faster, rattle under load.
A4: Rustbelt Cyber Trilobit | B4: trl_imp_x103 | C4: Head / cortex | D4: 1 | E4: 10800 | F4: =ROUND(E4*0.8,0) -> 8640 | G4: 1 | H4: head | I4: 22 | J4: ='Power Model'!$B$3*2^(D4-2) -> 0.5 | L4: =ROUND(E4*'Power Model'!$B$11,0) -> 2700 | M4: =ROUND(J4*'Power Model'!$B$4*('Power Model'!$B$7*'Power Model'!$B$8+'Power Model'!$B$9)+E4*'Power Model'!$B$10/100,0) -> 632 | O4: Implementation +1 | P4: 2 | Q4: Implementation 2 | R4: Brain implant: holds 2 nanohack slots. Durability gain is minimal. Cheap clinic parts: wear out faster, rattle under load.
A5: Backalley Works Trilobit | B5: trl_imp_x104 | C5: Head / cortex | D5: 1 | E5: 11200 | F5: =ROUND(E5*0.8,0) -> 8960 | G5: 1 | H5: head | I5: 24 | J5: ='Power Model'!$B$3*2^(D5-2) -> 0.5 | L5: =ROUND(E5*'Power Model'!$B$11,0) -> 2800 | M5: =ROUND(J5*'Power Model'!$B$4*('Power Model'!$B$7*'Power Model'!$B$8+'Power Model'!$B$9)+E5*'Power Model'!$B$10/100,0) -> 652 | O5: Research +1 | P5: 2 | Q5: Research 2 | R5: Brain implant: holds 2 nanohack slots. Durability gain is minimal. Cheap clinic parts: wear out faster, rattle under load.
A6: Gutterline Optic | B6: trl_imp_x105 | C6: Eyes | D6: 1 | E6: 12900 | F6: =ROUND(E6*0.8,0) -> 10320 | G6: 1 | H6: head | I6: 17 | J6: ='Power Model'!$B$3*2^(D6-2) -> 0.5 | L6: =ROUND(E6*'Power Model'!$B$11,0) -> 3225 | M6: =ROUND(J6*'Power Model'!$B$4*('Power Model'!$B$7*'Power Model'!$B$8+'Power Model'!$B$9)+E6*'Power Model'!$B$10/100,0) -> 737 | O6: Streetwise +1 | Q6: Streetwise 2 | R6: Durability gain is minimal. Cheap clinic parts: wear out faster, rattle under load.
A7: Kowloon Surplus Lens | B7: trl_imp_x106 | C7: Eyes | D7: 1 | E7: 13400 | F7: =ROUND(E7*0.8,0) -> 10720 | G7: 1 | H7: head | I7: 20 | J7: ='Power Model'!$B$3*2^(D7-2) -> 0.5 | L7: =ROUND(E7*'Power Model'!$B$11,0) -> 3350 | M7: =ROUND(J7*'Power Model'!$B$4*('Power Model'!$B$7*'Power Model'!$B$8+'Power Model'!$B$9)+E7*'Power Model'!$B$10/100,0) -> 762 | O7: Analysis +1 | Q7: Analysis 2 | R7: Durability gain is minimal. Cheap clinic parts: wear out faster, rattle under load.
A8: Rustbelt Cyber Scope | B8: trl_imp_x107 | C8: Eyes | D8: 1 | E8: 5800 | F8: =ROUND(E8*0.8,0) -> 4640 | G8: 1 | H8: head | I8: 40 | J8: ='Power Model'!$B$3*2^(D8-2) -> 0.5 | L8: =ROUND(E8*'Power Model'!$B$11,0) -> 1450 | M8: =ROUND(J8*'Power Model'!$B$4*('Power Model'!$B$7*'Power Model'!$B$8+'Power Model'!$B$9)+E8*'Power Model'!$B$10/100,0) -> 382 | Q8: None | R8: Durability gain is minimal. Cheap clinic parts: wear out faster, rattle under load.
A9: Backalley Works Reflex Wiring | B9: trl_imp_x108 | C9: Spine | D9: 1 | E9: 12900 | F9: =ROUND(E9*0.8,0) -> 10320 | G9: 2 | H9: chest | I9: 17 | J9: ='Power Model'!$B$3*2^(D9-2) -> 0.5 | L9: =ROUND(E9*'Power Model'!$B$11,0) -> 3225 | M9: =ROUND(J9*'Power Model'!$B$4*('Power Model'!$B$7*'Power Model'!$B$8+'Power Model'!$B$9)+E9*'Power Model'!$B$10/100,0) -> 737 | O9: Melee +1 | Q9: Melee 2 | R9: Durability gain is minimal. Cheap clinic parts: wear out faster, rattle under load.
A10: Gutterline Balance Rod | B10: trl_imp_x109 | C10: Spine | D10: 1 | E10: 13400 | F10: =ROUND(E10*0.8,0) -> 10720 | G10: 1 | H10: chest | I10: 20 | J10: ='Power Model'!$B$3*2^(D10-2) -> 0.5 | L10: =ROUND(E10*'Power Model'!$B$11,0) -> 3350 | M10: =ROUND(J10*'Power Model'!$B$4*('Power Model'!$B$7*'Power Model'!$B$8+'Power Model'!$B$9)+E10*'Power Model'!$B$10/100,0) -> 762 | O10: Dodge +1 | Q10: Dodge 2 | R10: Durability gain is minimal. Cheap clinic parts: wear out faster, rattle under load.
A11: Kowloon Surplus Nerve Weave | B11: trl_imp_x110 | C11: Spine | D11: 1 | E11: 5800 | F11: =ROUND(E11*0.8,0) -> 4640 | G11: 2 | H11: chest | I11: 40 | J11: ='Power Model'!$B$3*2^(D11-2) -> 0.5 | L11: =ROUND(E11*'Power Model'!$B$11,0) -> 1450 | M11: =ROUND(J11*'Power Model'!$B$4*('Power Model'!$B$7*'Power Model'!$B$8+'Power Model'!$B$9)+E11*'Power Model'!$B$10/100,0) -> 382 | Q11: None | R11: Durability gain is minimal. Cheap clinic parts: wear out faster, rattle under load.
A12: Rustbelt Cyber Lung Pack | B12: trl_imp_x111 | C12: Chest / organs | D12: 1 | E12: 12900 | F12: =ROUND(E12*0.8,0) -> 10320 | G12: 1 | H12: chest | I12: 17 | J12: ='Power Model'!$B$3*2^(D12-2) -> 0.5 | K12: ='Power Model'!$B$4*'Power Model'!$B$5*J12 -> 672 | L12: =ROUND(E12*'Power Model'!$B$11,0) -> 3225 | M12: =ROUND(J12*'Power Model'!$B$4*('Power Model'!$B$7*'Power Model'!$B$8+'Power Model'!$B$9)+E12*'Power Model'!$B$10/100,0) -> 737 | N12: =ROUND(K12*('Power Model'!$B$7*'Power Model'!$B$8+'Power Model'!$B$9),0) -> 739 | O12: Manual +1 | Q12: Manual 2 | R12: Chest battery. Durability gain is minimal. Cheap clinic parts: wear out faster, rattle under load.
A13: Backalley Works Heart Pump | B13: trl_imp_x112 | C13: Chest / organs | D13: 1 | E13: 13400 | F13: =ROUND(E13*0.8,0) -> 10720 | G13: 2 | H13: chest | I13: 20 | J13: ='Power Model'!$B$3*2^(D13-2) -> 0.5 | K13: ='Power Model'!$B$4*'Power Model'!$B$5*J13 -> 672 | L13: =ROUND(E13*'Power Model'!$B$11,0) -> 3350 | M13: =ROUND(J13*'Power Model'!$B$4*('Power Model'!$B$7*'Power Model'!$B$8+'Power Model'!$B$9)+E13*'Power Model'!$B$10/100,0) -> 762 | N13: =ROUND(K13*('Power Model'!$B$7*'Power Model'!$B$8+'Power Model'!$B$9),0) -> 739 | O13: Grit +1 | Q13: Grit 2 | R13: Chest battery. Durability gain is minimal. Cheap clinic parts: wear out faster, rattle under load.
A14: Gutterline Reserve Cell | B14: trl_imp_x113 | C14: Chest / organs | D14: 1 | E14: 20300 | F14: =ROUND(E14*0.8,0) -> 16240 | G14: 1 | H14: chest | I14: 40 | J14: ='Power Model'!$B$3*2^(D14-2) -> 0.5 | K14: ='Power Model'!$B$4*'Power Model'!$B$5*J14*'Power Model'!$B$12 -> 2016 | L14: =ROUND(E14*'Power Model'!$B$11,0) -> 5075 | M14: =ROUND(J14*'Power Model'!$B$4*('Power Model'!$B$7*'Power Model'!$B$8+'Power Model'!$B$9)+E14*'Power Model'!$B$10/100,0) -> 1107 | N14: =ROUND(K14*('Power Model'!$B$7*'Power Model'!$B$8+'Power Model'!$B$9),0) -> 2218 | Q14: None | R14: Reserve battery: stores 3x the standard chest battery, no skill bonus. Durability gain is minimal. Cheap clinic parts: wear out faster, rattle under load.
A15: Kowloon Surplus Dermal Plate | B15: trl_imp_x114 | C15: Dermal | D15: 1 | E15: 5500 | F15: =ROUND(E15*0.8,0) -> 4400 | G15: 2 | H15: all limbs | I15: 36 | J15: ='Power Model'!$B$3*2^(D15-2) -> 0.5 | L15: =ROUND(E15*'Power Model'!$B$11,0) -> 1375 | M15: =ROUND(J15*'Power Model'!$B$4*('Power Model'!$B$7*'Power Model'!$B$8+'Power Model'!$B$9)+E15*'Power Model'!$B$10/100,0) -> 367 | O15: Negotiation -1 | Q15: None | R15: Dermal layer: armor-focused, stiff skin costs Negotiation -1. Durability gain is minimal. Cheap clinic parts: wear out faster, rattle under load.
A16: Rustbelt Cyber Skin Weave | B16: trl_imp_x115 | C16: Dermal | D16: 1 | E16: 5700 | F16: =ROUND(E16*0.8,0) -> 4560 | G16: 2 | H16: all limbs | I16: 39 | J16: ='Power Model'!$B$3*2^(D16-2) -> 0.5 | L16: =ROUND(E16*'Power Model'!$B$11,0) -> 1425 | M16: =ROUND(J16*'Power Model'!$B$4*('Power Model'!$B$7*'Power Model'!$B$8+'Power Model'!$B$9)+E16*'Power Model'!$B$10/100,0) -> 377 | O16: Negotiation -1 | Q16: None | R16: Dermal layer: armor-focused, stiff skin costs Negotiation -1. Durability gain is minimal. Cheap clinic parts: wear out faster, rattle under load.
A17: Backalley Works Forearm Frame | B17: trl_imp_x116 | C17: Arms | D17: 1 | E17: 5400 | F17: =ROUND(E17*0.8,0) -> 4320 | G17: 2 | H17: arms | I17: 34 | J17: ='Power Model'!$B$3*2^(D17-2) -> 0.5 | L17: =ROUND(E17*'Power Model'!$B$11,0) -> 1350 | M17: =ROUND(J17*'Power Model'!$B$4*('Power Model'!$B$7*'Power Model'!$B$8+'Power Model'!$B$9)+E17*'Power Model'!$B$10/100,0) -> 362 | Q17: None | R17: Durability gain is minimal. Cheap clinic parts: wear out faster, rattle under load.
A18: Gutterline Strike Servo | B18: trl_imp_x117 | C18: Arms | D18: 1 | E18: 13400 | F18: =ROUND(E18*0.8,0) -> 10720 | G18: 1 | H18: arms | I18: 20 | J18: ='Power Model'!$B$3*2^(D18-2) -> 0.5 | L18: =ROUND(E18*'Power Model'!$B$11,0) -> 3350 | M18: =ROUND(J18*'Power Model'!$B$4*('Power Model'!$B$7*'Power Model'!$B$8+'Power Model'!$B$9)+E18*'Power Model'!$B$10/100,0) -> 762 | O18: Melee +1 | Q18: Melee 2 | R18: Durability gain is minimal. Cheap clinic parts: wear out faster, rattle under load.
A19: Kowloon Surplus Haul Cabling | B19: trl_imp_x118 | C19: Arms | D19: 1 | E19: 13900 | F19: =ROUND(E19*0.8,0) -> 11120 | G19: 2 | H19: arms | I19: 23 | J19: ='Power Model'!$B$3*2^(D19-2) -> 0.5 | L19: =ROUND(E19*'Power Model'!$B$11,0) -> 3475 | M19: =ROUND(J19*'Power Model'!$B$4*('Power Model'!$B$7*'Power Model'!$B$8+'Power Model'!$B$9)+E19*'Power Model'!$B$10/100,0) -> 787 | O19: Unarmed +1 | Q19: Unarmed 2 | R19: Durability gain is minimal. Cheap clinic parts: wear out faster, rattle under load.
A20: Rustbelt Cyber Smart Palm | B20: trl_imp_x119 | C20: Hands | D20: 1 | E20: 5400 | F20: =ROUND(E20*0.8,0) -> 4320 | G20: 1 | H20: arms | I20: 34 | J20: ='Power Model'!$B$3*2^(D20-2) -> 0.5 | L20: =ROUND(E20*'Power Model'!$B$11,0) -> 1350 | M20: =ROUND(J20*'Power Model'!$B$4*('Power Model'!$B$7*'Power Model'!$B$8+'Power Model'!$B$9)+E20*'Power Model'!$B$10/100,0) -> 362 | Q20: None | R20: Durability gain is minimal. Cheap clinic parts: wear out faster, rattle under load.
A21: Backalley Works Fine-Motor Set | B21: trl_imp_x120 | C21: Hands | D21: 1 | E21: 13400 | F21: =ROUND(E21*0.8,0) -> 10720 | G21: 2 | H21: arms | I21: 20 | J21: ='Power Model'!$B$3*2^(D21-2) -> 0.5 | L21: =ROUND(E21*'Power Model'!$B$11,0) -> 3350 | M21: =ROUND(J21*'Power Model'!$B$4*('Power Model'!$B$7*'Power Model'!$B$8+'Power Model'!$B$9)+E21*'Power Model'!$B$10/100,0) -> 762 | O21: Engineering +1 | Q21: Engineering 2 | R21: Durability gain is minimal. Cheap clinic parts: wear out faster, rattle under load.
A22: Gutterline Tool Fingers | B22: trl_imp_x121 | C22: Hands | D22: 1 | E22: 13900 | F22: =ROUND(E22*0.8,0) -> 11120 | G22: 1 | H22: arms | I22: 23 | J22: ='Power Model'!$B$3*2^(D22-2) -> 0.5 | L22: =ROUND(E22*'Power Model'!$B$11,0) -> 3475 | M22: =ROUND(J22*'Power Model'!$B$4*('Power Model'!$B$7*'Power Model'!$B$8+'Power Model'!$B$9)+E22*'Power Model'!$B$10/100,0) -> 787 | O22: Artisan +1 | Q22: Artisan 2 | R22: Durability gain is minimal. Cheap clinic parts: wear out faster, rattle under load.
A23: Kowloon Surplus Actuator | B23: trl_imp_x122 | C23: Legs | D23: 1 | E23: 5400 | F23: =ROUND(E23*0.8,0) -> 4320 | G23: 2 | H23: legs | I23: 34 | J23: ='Power Model'!$B$3*2^(D23-2) -> 0.5 | L23: =ROUND(E23*'Power Model'!$B$11,0) -> 1350 | M23: =ROUND(J23*'Power Model'!$B$4*('Power Model'!$B$7*'Power Model'!$B$8+'Power Model'!$B$9)+E23*'Power Model'!$B$10/100,0) -> 362 | Q23: None | R23: Durability gain is minimal. Cheap clinic parts: wear out faster, rattle under load.
A24: Rustbelt Cyber Shock Spring | B24: trl_imp_x123 | C24: Legs | D24: 1 | E24: 13400 | F24: =ROUND(E24*0.8,0) -> 10720 | G24: 1 | H24: legs | I24: 20 | J24: ='Power Model'!$B$3*2^(D24-2) -> 0.5 | L24: =ROUND(E24*'Power Model'!$B$11,0) -> 3350 | M24: =ROUND(J24*'Power Model'!$B$4*('Power Model'!$B$7*'Power Model'!$B$8+'Power Model'!$B$9)+E24*'Power Model'!$B$10/100,0) -> 762 | O24: Streetwise +1 | Q24: Streetwise 2 | R24: Durability gain is minimal. Cheap clinic parts: wear out faster, rattle under load.
A25: Backalley Works Sprint Tendons | B25: trl_imp_x124 | C25: Legs | D25: 1 | E25: 13900 | F25: =ROUND(E25*0.8,0) -> 11120 | G25: 2 | H25: legs | I25: 23 | J25: ='Power Model'!$B$3*2^(D25-2) -> 0.5 | L25: =ROUND(E25*'Power Model'!$B$11,0) -> 3475 | M25: =ROUND(J25*'Power Model'!$B$4*('Power Model'!$B$7*'Power Model'!$B$8+'Power Model'!$B$9)+E25*'Power Model'!$B$10/100,0) -> 787 | O25: Manual +1 | Q25: Manual 2 | R25: Durability gain is minimal. Cheap clinic parts: wear out faster, rattle under load.
A26: Halden Medical Trilobit | B26: trl_imp_x201 | C26: Head / cortex | D26: 2 | E26: 24800 | F26: =ROUND(E26*0.8,0) -> 19840 | G26: 2 | H26: head | I26: 26 | J26: ='Power Model'!$B$3*2^(D26-2) -> 1 | L26: =ROUND(E26*'Power Model'!$B$11,0) -> 6200 | M26: =ROUND(J26*'Power Model'!$B$4*('Power Model'!$B$7*'Power Model'!$B$8+'Power Model'!$B$9)+E26*'Power Model'!$B$10/100,0) -> 1425 | O26: Networking +1 | P26: 4 | Q26: Networking 2; Grit 1 | R26: Brain implant: holds 4 nanohack slots. Reliable street-clinic grade.
A27: Sumida-Reyes Trilobit | B27: trl_imp_x202 | C27: Head / cortex | D27: 2 | E27: 25900 | F27: =ROUND(E27*0.8,0) -> 20720 | G27: 2 | H27: head | I27: 28 | J27: ='Power Model'!$B$3*2^(D27-2) -> 1 | L27: =ROUND(E27*'Power Model'!$B$11,0) -> 6475 | M27: =ROUND(J27*'Power Model'!$B$4*('Power Model'!$B$7*'Power Model'!$B$8+'Power Model'!$B$9)+E27*'Power Model'!$B$10/100,0) -> 1480 | O27: Analysis +1 | P27: 4 | Q27: Analysis 2; Grit 1 | R27: Brain implant: holds 4 nanohack slots. Reliable street-clinic grade.
A28: Brightwater Biomed Trilobit | B28: trl_imp_x203 | C28: Head / cortex | D28: 2 | E28: 26900 | F28: =ROUND(E28*0.8,0) -> 21520 | G28: 2 | H28: head | I28: 32 | J28: ='Power Model'!$B$3*2^(D28-2) -> 1 | L28: =ROUND(E28*'Power Model'!$B$11,0) -> 6725 | M28: =ROUND(J28*'Power Model'!$B$4*('Power Model'!$B$7*'Power Model'!$B$8+'Power Model'!$B$9)+E28*'Power Model'!$B$10/100,0) -> 1530 | O28: Implementation +1 | P28: 4 | Q28: Implementation 2; Grit 1 | R28: Brain implant: holds 4 nanohack slots. Reliable street-clinic grade.
A29: Corvane Trilobit | B29: trl_imp_x204 | C29: Head / cortex | D29: 2 | E29: 28000 | F29: =ROUND(E29*0.8,0) -> 22400 | G29: 2 | H29: head | I29: 34 | J29: ='Power Model'!$B$3*2^(D29-2) -> 1 | L29: =ROUND(E29*'Power Model'!$B$11,0) -> 7000 | M29: =ROUND(J29*'Power Model'!$B$4*('Power Model'!$B$7*'Power Model'!$B$8+'Power Model'!$B$9)+E29*'Power Model'!$B$10/100,0) -> 1585 | O29: Research +1 | P29: 4 | Q29: Research 2; Grit 1 | R29: Brain implant: holds 4 nanohack slots. Reliable street-clinic grade.
A30: Halden Medical Optic | B30: trl_imp_x205 | C30: Eyes | D30: 2 | E30: 30000 | F30: =ROUND(E30*0.8,0) -> 24000 | G30: 2 | H30: head | I30: 27 | J30: ='Power Model'!$B$3*2^(D30-2) -> 1 | L30: =ROUND(E30*'Power Model'!$B$11,0) -> 7500 | M30: =ROUND(J30*'Power Model'!$B$4*('Power Model'!$B$7*'Power Model'!$B$8+'Power Model'!$B$9)+E30*'Power Model'!$B$10/100,0) -> 1685 | O30: Streetwise +1 | Q30: Streetwise 2; Grit 1 | R30: Reliable street-clinic grade.
A31: Sumida-Reyes Lens | B31: trl_imp_x206 | C31: Eyes | D31: 2 | E31: 31200 | F31: =ROUND(E31*0.8,0) -> 24960 | G31: 2 | H31: head | I31: 30 | J31: ='Power Model'!$B$3*2^(D31-2) -> 1 | L31: =ROUND(E31*'Power Model'!$B$11,0) -> 7800 | M31: =ROUND(J31*'Power Model'!$B$4*('Power Model'!$B$7*'Power Model'!$B$8+'Power Model'!$B$9)+E31*'Power Model'!$B$10/100,0) -> 1745 | O31: Analysis +1 | Q31: Analysis 2; Grit 1 | R31: Reliable street-clinic grade.
A32: Brightwater Biomed Scope | B32: trl_imp_x207 | C32: Eyes | D32: 2 | E32: 32400 | F32: =ROUND(E32*0.8,0) -> 25920 | G32: 2 | H32: head | I32: 33 | J32: ='Power Model'!$B$3*2^(D32-2) -> 1 | L32: =ROUND(E32*'Power Model'!$B$11,0) -> 8100 | M32: =ROUND(J32*'Power Model'!$B$4*('Power Model'!$B$7*'Power Model'!$B$8+'Power Model'!$B$9)+E32*'Power Model'!$B$10/100,0) -> 1805 | O32: Ranged +1 | Q32: Ranged 2; Grit 1 | R32: Reliable street-clinic grade.
A33: Corvane Reflex Wiring | B33: trl_imp_x208 | C33: Spine | D33: 2 | E33: 30000 | F33: =ROUND(E33*0.8,0) -> 24000 | G33: 3 | H33: chest | I33: 27 | J33: ='Power Model'!$B$3*2^(D33-2) -> 1 | L33: =ROUND(E33*'Power Model'!$B$11,0) -> 7500 | M33: =ROUND(J33*'Power Model'!$B$4*('Power Model'!$B$7*'Power Model'!$B$8+'Power Model'!$B$9)+E33*'Power Model'!$B$10/100,0) -> 1685 | O33: Melee +1 | Q33: Melee 2; Grit 1 | R33: Reliable street-clinic grade.
A34: Halden Medical Balance Rod | B34: trl_imp_x209 | C34: Spine | D34: 2 | E34: 31200 | F34: =ROUND(E34*0.8,0) -> 24960 | G34: 2 | H34: chest | I34: 30 | J34: ='Power Model'!$B$3*2^(D34-2) -> 1 | L34: =ROUND(E34*'Power Model'!$B$11,0) -> 7800 | M34: =ROUND(J34*'Power Model'!$B$4*('Power Model'!$B$7*'Power Model'!$B$8+'Power Model'!$B$9)+E34*'Power Model'!$B$10/100,0) -> 1745 | O34: Dodge +1 | Q34: Dodge 2; Grit 1 | R34: Reliable street-clinic grade.
A35: Sumida-Reyes Nerve Weave | B35: trl_imp_x210 | C35: Spine | D35: 2 | E35: 32400 | F35: =ROUND(E35*0.8,0) -> 25920 | G35: 3 | H35: chest | I35: 33 | J35: ='Power Model'!$B$3*2^(D35-2) -> 1 | L35: =ROUND(E35*'Power Model'!$B$11,0) -> 8100 | M35: =ROUND(J35*'Power Model'!$B$4*('Power Model'!$B$7*'Power Model'!$B$8+'Power Model'!$B$9)+E35*'Power Model'!$B$10/100,0) -> 1805 | O35: Unarmed +1 | Q35: Unarmed 2; Grit 1 | R35: Reliable street-clinic grade.
A36: Brightwater Biomed Lung Pack | B36: trl_imp_x211 | C36: Chest / organs | D36: 2 | E36: 30000 | F36: =ROUND(E36*0.8,0) -> 24000 | G36: 2 | H36: chest | I36: 27 | J36: ='Power Model'!$B$3*2^(D36-2) -> 1 | K36: ='Power Model'!$B$4*'Power Model'!$B$5*J36 -> 1344 | L36: =ROUND(E36*'Power Model'!$B$11,0) -> 7500 | M36: =ROUND(J36*'Power Model'!$B$4*('Power Model'!$B$7*'Power Model'!$B$8+'Power Model'!$B$9)+E36*'Power Model'!$B$10/100,0) -> 1685 | N36: =ROUND(K36*('Power Model'!$B$7*'Power Model'!$B$8+'Power Model'!$B$9),0) -> 1478 | O36: Manual +1 | Q36: Manual 2; Grit 1 | R36: Chest battery. Reliable street-clinic grade.
A37: Corvane Heart Pump | B37: trl_imp_x212 | C37: Chest / organs | D37: 2 | E37: 31200 | F37: =ROUND(E37*0.8,0) -> 24960 | G37: 3 | H37: chest | I37: 30 | J37: ='Power Model'!$B$3*2^(D37-2) -> 1 | K37: ='Power Model'!$B$4*'Power Model'!$B$5*J37 -> 1344 | L37: =ROUND(E37*'Power Model'!$B$11,0) -> 7800 | M37: =ROUND(J37*'Power Model'!$B$4*('Power Model'!$B$7*'Power Model'!$B$8+'Power Model'!$B$9)+E37*'Power Model'!$B$10/100,0) -> 1745 | N37: =ROUND(K37*('Power Model'!$B$7*'Power Model'!$B$8+'Power Model'!$B$9),0) -> 1478 | O37: Grit +1 | Q37: Grit 2 | R37: Chest battery. Reliable street-clinic grade.
A38: Halden Medical Reserve Cell | B38: trl_imp_x213 | C38: Chest / organs | D38: 2 | E38: 46000 | F38: =ROUND(E38*0.8,0) -> 36800 | G38: 2 | H38: chest | I38: 59 | J38: ='Power Model'!$B$3*2^(D38-2) -> 1 | K38: ='Power Model'!$B$4*'Power Model'!$B$5*J38*'Power Model'!$B$12 -> 4032 | L38: =ROUND(E38*'Power Model'!$B$11,0) -> 11500 | M38: =ROUND(J38*'Power Model'!$B$4*('Power Model'!$B$7*'Power Model'!$B$8+'Power Model'!$B$9)+E38*'Power Model'!$B$10/100,0) -> 2485 | N38: =ROUND(K38*('Power Model'!$B$7*'Power Model'!$B$8+'Power Model'!$B$9),0) -> 4435 | Q38: Grit 1 | R38: Reserve battery: stores 3x the standard chest battery, no skill bonus. Reliable street-clinic grade.
A39: Sumida-Reyes Dermal Plate | B39: trl_imp_x214 | C39: Dermal | D39: 2 | E39: 30600 | F39: =ROUND(E39*0.8,0) -> 24480 | G39: 3 | H39: all limbs | I39: 28 | J39: ='Power Model'!$B$3*2^(D39-2) -> 1 | L39: =ROUND(E39*'Power Model'!$B$11,0) -> 7650 | M39: =ROUND(J39*'Power Model'!$B$4*('Power Model'!$B$7*'Power Model'!$B$8+'Power Model'!$B$9)+E39*'Power Model'!$B$10/100,0) -> 1715 | O39: Grit +1; Negotiation -1 | Q39: Grit 2 | R39: Dermal layer: armor-focused, stiff skin costs Negotiation -1. Reliable street-clinic grade.
A40: Brightwater Biomed Skin Weave | B40: trl_imp_x215 | C40: Dermal | D40: 2 | E40: 18200 | F40: =ROUND(E40*0.8,0) -> 14560 | G40: 3 | H40: all limbs | I40: 58 | J40: ='Power Model'!$B$3*2^(D40-2) -> 1 | L40: =ROUND(E40*'Power Model'!$B$11,0) -> 4550 | M40: =ROUND(J40*'Power Model'!$B$4*('Power Model'!$B$7*'Power Model'!$B$8+'Power Model'!$B$9)+E40*'Power Model'!$B$10/100,0) -> 1095 | O40: Negotiation -1 | Q40: Grit 1 | R40: Dermal layer: armor-focused, stiff skin costs Negotiation -1. Reliable street-clinic grade.
...

Sheet Power Model
A1: Power and cost model (edit the yellow cells; the Example Implants tab recalculates)
A3: Latent draw of one Improved (grade 2) implant, kJ/h | B3: 1 | C3: Draft. Each grade doubles it: draw = this x 2^(grade-2).
A4: Hours in a week of full use | B4: 168
A5: Implants in a fully implanted person (one per layer) | B5: 8 | C5: Head, eyes, spine, chest, dermal, arms, hands, legs.
A6: Improved chest battery capacity, kJ | B6: =B3*B4*B5 -> 1344 | C6: =week x rig size x draw. an all-improved rig drains it in exactly one week. -> #VALUE!
A7: Power rate, yen per kJ | B7: 1 | C7: Same as the charging stations (POWER_RATE).
A8: District multiplier | B8: 1 | C8: 0.85 lower, 1.0 middle, 1.35 upper.
A9: Power tax, yen per kJ | B9: 0.1 | C9: Same as the charging stations (POWER_TAX).
A10: Implant tax, % of implant price per visit | B10: 5 | C10: Same as the charging stations (TAX_PCT).
A11: Repair cost at 100% damage, fraction of price | B11: 0.25 | C11: Quality fee scales linearly with damage.
A12: Reserve Cell capacity multiplier | B12: 3 | C12: Extra chest implants store this many times the standard battery of their grade.
A14: Check: hours an all-Improved rig runs on one Improved battery | B14: =B6/(B5*B3) -> 168 | C14: Should read 168.

Sheet Notes
A1: Tab 1 (Implants): the 12 implants in the game today. Edits here do not change the game.
A2: Tab 2 (Example Implants): invented designs, 24 per quality level plus one extra Prototype Trilobit. Not in the game.
A3: Quality levels by grade: 1 Basic, 2 Improved, 3 Quality, 4 Military, 5 Prototype (grade 5 is new).
A4: Durability doubles as health. Within a level, implants with smaller skill bonuses get more durability: dur = low + (high x 1.25 - low) x (1 - skill total / highest skill total in the level).
A5: Armor: every implant has at least 1; dermal implants are the armor-heavy layer. Armor applies to the limb group of the part (eyes: head, spine: chest, hands: arms).
A6: Layers: Chest and Dermal are separate. Dermal implants all lower Negotiation by 1.
A7: Nanohacks permitted (Trilobits only): Basic 2, Improved 4, Quality 6, Military 8, Prototype 10; the extra Prototype Trilobit holds 14 and has no skill bonus.
A8: Latent draw = Power Model!B3 x 2^(grade-2). An all-Improved rig of 8 implants (one per layer) drains one Improved chest battery in 168 hours.
A9: Battery: standard chest batteries store week x rig size x draw of their grade (they double per grade). Reserve Cells store 3x that and have no skill bonus.
A10: Prices are 10x the earlier example prices. Underground clinics charge 80%.
A11: Quality fee = the repair cost: 25% of price at 100% damage, scaling with damage.
A12: Recharge cost (one week) = draw x 168 h x (power rate x district + power tax) + implant tax on the price. It leaves out the old per-visit quality fee because that fee is now the repair cost.
... A14: Manufacturers and model names are invented.
